.F
======================================================================
FAIL: test_aoc_part2 (test_aoc_2021_8.TestAOC)
----------------------------------------------------------------------
Traceback (most recent call last):
  File "/sandbox/test_aoc_2021_8.py", line 11, in test_aoc_part2
    self.assertEqual(5353, get_number_part2('input3.txt'))
AssertionError: 5353 != 26

----------------------------------------------------------------------
Ran 2 tests in 0.000s

FAILED (failures=1)
